<?xml version="1.0" ?>
<!-- =================================================================================== -->
<!-- |    This document was autogenerated by xacro from /home/syed/manipulator_ws/src/robot_description/urdf/manipulator.urdf.xacro | -->
<!-- |    EDITING THIS FILE BY HAND IS NOT RECOMMENDED                                 | -->
<!-- =================================================================================== -->
<!-- <robot>  </robot> tags are the root elements of the URDF -->
<!-- Name of the robot is "manipulator" -->
<robot name="manipulator">
  <!--if using Gazebo Harmonic (default="false") and Gazebo Ignition (default="true") -->
  <!-- ROS 2 Control -->
  <gazebo>
    <plugin filename="gz_ros2_control-system" name="gz_ros2_control::GazeboSimROS2ControlPlugin">
      <parameters>/home/syed/manipulator_ws/install/manipulator_controller/share/manipulator_controller/config/manipulator_controller.yaml</parameters>
    </plugin>
  </gazebo>
  <gazebo reference="base_link">
    <mu1>0.2</mu1>
    <mu2>0.2</mu2>
    <material>Gazebo/Blue</material>
  </gazebo>
  <gazebo reference="base_plate">
    <mu1>0.2</mu1>
    <mu2>0.2</mu2>
    <material>Gazebo/Blue</material>
  </gazebo>
  <gazebo reference="forward_drive_arm">
    <mu1>0.2</mu1>
    <mu2>0.2</mu2>
    <material>Gazebo/Blue</material>
  </gazebo>
  <gazebo reference="horizontal_arm">
    <mu1>0.2</mu1>
    <mu2>0.2</mu2>
    <material>Gazebo/Blue</material>
  </gazebo>
  <gazebo reference="claw_support">
    <mu1>0.2</mu1>
    <mu2>0.2</mu2>
    <material>Gazebo/Blue</material>
  </gazebo>
  <gazebo reference="gripper_finger_left">
    <mu1>0.2</mu1>
    <mu2>0.2</mu2>
    <material>Gazebo/Blue</material>
  </gazebo>
  <gazebo reference="gripper_finger_right">
    <mu1>0.2</mu1>
    <mu2>0.2</mu2>
    <material>Gazebo/Blue</material>
  </gazebo>
  <ros2_control name="RobotSystem" type="system">
    <hardware>
      <plugin>gz_ros2_control/GazeboSimSystem</plugin>
      <!-- Ignition Gazebo ROS2 humble control plugin -->
    </hardware>
    <!-- Joints Configuration -->
    <joint name="basement_to_base_plate">
      <command_interface name="position">
        <!-- command interface for position control -->
        <param name="min"> -1.570795 </param>
        <param name="max"> 1.570795 </param>
      </command_interface>
      <state_interface name="position"/>
      <!-- state interface to read the position -->
    </joint>
    <joint name="base_plate_to_forward_drive_arm">
      <command_interface name="position">
        <!-- command interface for position control -->
        <param name="min"> -1.570795 </param>
        <param name="max"> 1.570795 </param>
      </command_interface>
      <state_interface name="position"/>
      <!-- state interface to read the position -->
    </joint>
    <joint name="forward_drive_arm_to_horizontal_arm">
      <command_interface name="position">
        <!-- command interface for position control -->
        <param name="min"> -1.570795 </param>
        <param name="max"> 1.570795 </param>
      </command_interface>
      <state_interface name="position"/>
      <!-- state interface to read the position -->
    </joint>
    <!-- These joints are for the gripper -->
    <joint name="claw_support_to_gripper_finger_left">
      <command_interface name="position">
        <!-- command interface for position control -->
        <param name="min"> -1.570795 </param>
        <param name="max"> 0.0 </param>
      </command_interface>
      <state_interface name="position"/>
      <!-- state interface to read the position -->
    </joint>
    <joint name="claw_support_to_gripper_finger_right">
      <param name="mimic">claw_support_to_gripper_finger_left</param>
      <!-- mimic joint to follow claw_support_to_gripper_finger_left -->
      <param name="multiplier">-1</param>
      <!-- inverse movement -->
    </joint>
  </ros2_control>
  <!-- Define the robot's links and joints -->
  <link name="world"/>
  <link name="base_link">
    <!--only change the mass -->
    <inertial>
      <mass value="1.0"/>
      <inertia ixx="0.1" ixy="0.0" ixz="0.0" iyy="0.1" iyz="0.0" izz="0.1"/>
    </inertial>
    <visual>
      <!-- Displacement and orientation  of the geometric center of the link with respect to previous link-->
      <origin rpy="0.0 0.0 0.0" xyz="-0.5 -0.5 0.0"/>
      <geometry>
        <mesh filename="package://robot_description/meshes/basement.STL" scale="0.01 0.01 0.01"/>
      </geometry>
      <material name="blue">
        <color rgba="0 0 1 1"/>
      </material>
    </visual>
    <collision>
      <origin rpy="0.0 0.0 0.0" xyz="-0.5 -0.5 0.0"/>
      <geometry>
        <mesh filename="package://robot_description/meshes/basement.STL" scale="0.01 0.01 0.01"/>
      </geometry>
    </collision>
  </link>
  <!--2nd part-->
  <link name="base_plate">
    <!--only change the mass -->
    <inertial>
      <mass value="0.1"/>
      <inertia ixx="0.1" ixy="0.0" ixz="0.0" iyy="0.1" iyz="0.0" izz="0.1"/>
    </inertial>
    <visual>
      <origin rpy="0 0 0" xyz="-0.36 -0.40 -0.56"/>
      <geometry>
        <mesh filename="package://robot_description/meshes/base_plate.STL" scale="0.01 0.01 0.01"/>
      </geometry>
      <material name="blue">
        <color rgba="0 0 1 1"/>
      </material>
    </visual>
    <collision>
      <origin rpy="0 0 0" xyz="-0.36 -0.40 -0.56"/>
      <geometry>
        <mesh filename="package://robot_description/meshes/base_plate.STL" scale="0.01 0.01 0.01"/>
      </geometry>
    </collision>
  </link>
  <!--3rd part-->
  <link name="forward_drive_arm">
    <!--only change the mass -->
    <inertial>
      <mass value="0.1"/>
      <inertia ixx="0.1" ixy="0.0" ixz="0.0" iyy="0.1" iyz="0.0" izz="0.1"/>
    </inertial>
    <visual>
      <origin rpy="0 -1.570795 1.570795" xyz="0.19 0.06 -0.08"/>
      <geometry>
        <mesh filename="package://robot_description/meshes/forward_drive_arm.STL" scale="0.01 0.01 0.01"/>
      </geometry>
      <material name="blue">
        <color rgba="0 0 1 1"/>
      </material>
    </visual>
    <collision>
      <origin rpy="0 -1.570795 1.570795" xyz="0.19 0.06 -0.08"/>
      <geometry>
        <mesh filename="package://robot_description/meshes/forward_drive_arm.STL" scale="0.01 0.01 0.01"/>
      </geometry>
    </collision>
  </link>
  <!--4th part -->
  <link name="horizontal_arm">
    <!--only change the mass -->
    <inertial>
      <mass value="0.1"/>
      <inertia ixx="0.1" ixy="0.0" ixz="0.0" iyy="0.1" iyz="0.0" izz="0.1"/>
    </inertial>
    <visual>
      <origin rpy="1.570795 0 1.570795" xyz="-0.03 -0.4 -0.06"/>
      <geometry>
        <mesh filename="package://robot_description/meshes/horizontal_arm.STL" scale="0.01 0.01 0.01"/>
      </geometry>
      <material name="blue">
        <color rgba="0 0 1 1"/>
      </material>
    </visual>
    <collision>
      <origin rpy="1.570795 0 1.570795" xyz="-0.03 -0.4 -0.06"/>
      <geometry>
        <mesh filename="package://robot_description/meshes/horizontal_arm.STL" scale="0.01 0.01 0.01"/>
      </geometry>
    </collision>
  </link>
  <!-- 5th part -->
  <link name="claw_support">
    <!--only change the mass -->
    <inertial>
      <mass value="0.05"/>
      <inertia ixx="0.1" ixy="0.0" ixz="0.0" iyy="0.1" iyz="0.0" izz="0.1"/>
    </inertial>
    <visual>
      <origin rpy="0 0 1.570795" xyz="0.0 -0.05 -0.15"/>
      <geometry>
        <mesh filename="package://robot_description/meshes/claw_support.STL" scale="0.01 0.01 0.01"/>
      </geometry>
      <material name="blue">
        <color rgba="0 0 1 1"/>
      </material>
    </visual>
    <collision>
      <origin rpy="0 0 1.570795" xyz="0.0 -0.05 -0.15"/>
      <geometry>
        <mesh filename="package://robot_description/meshes/claw_support.STL" scale="0.01 0.01 0.01"/>
      </geometry>
    </collision>
  </link>
  <!-- gripper fingers -->
  <link name="gripper_finger_left">
    <!--only change the mass -->
    <inertial>
      <mass value="0.01"/>
      <inertia ixx="0.1" ixy="0.0" ixz="0.0" iyy="0.1" iyz="0.0" izz="0.1"/>
    </inertial>
    <visual>
      <origin rpy="0 0 -1.570795" xyz="-0.04 0.5 -0.1"/>
      <geometry>
        <mesh filename="package://robot_description/meshes/left_finger.STL" scale="0.01 0.01 0.01"/>
      </geometry>
      <material name="blue">
        <color rgba="0 0 1 1"/>
      </material>
    </visual>
    <collision>
      <origin rpy="0 0 -1.570795" xyz="-0.04 0.5 -0.1"/>
      <geometry>
        <mesh filename="package://robot_description/meshes/left_finger.STL" scale="0.01 0.01 0.01"/>
      </geometry>
    </collision>
  </link>
  <link name="gripper_finger_right">
    <!--only change the mass -->
    <inertial>
      <mass value="0.01"/>
      <inertia ixx="0.1" ixy="0.0" ixz="0.0" iyy="0.1" iyz="0.0" izz="0.1"/>
    </inertial>
    <visual>
      <origin rpy="0 0 -1.570795" xyz="-0.1 0.5 -0.1"/>
      <geometry>
        <mesh filename="package://robot_description/meshes/right_finger.STL" scale="0.01 0.01 0.01"/>
      </geometry>
      <material name="blue">
        <color rgba="0 0 1 1"/>
      </material>
    </visual>
    <collision>
      <origin rpy="0 0 -1.570795" xyz="-0.1 0.5 -0.1"/>
      <geometry>
        <mesh filename="package://robot_description/meshes/right_finger.STL" scale="0.01 0.01 0.01"/>
      </geometry>
    </collision>
  </link>
  <!-- CAMERA LINK     -->
  <link name="rgb_camera">
    <!--only change the mass -->
    <inertial>
      <mass value="0.01"/>
      <inertia ixx="0.1" ixy="0.0" ixz="0.0" iyy="0.1" iyz="0.0" izz="0.1"/>
    </inertial>
    <visual>
      <origin rpy="-1.5358884444793508 0 -1.570795" xyz="-0.09 0.13 0.13"/>
      <geometry>
        <mesh filename="package://robot_description/meshes/pi_camera.STL" scale="0.01 0.01 0.01"/>
      </geometry>
      <material name="blue">
        <color rgba="0 0 1 1"/>
      </material>
    </visual>
    <collision>
      <origin rpy="-1.5358884444793508 0 -1.570795" xyz="-0.09 0.13 0.13"/>
      <geometry>
        <mesh filename="package://robot_description/meshes/pi_camera.STL" scale="0.01 0.01 0.01"/>
      </geometry>
    </collision>
  </link>
  <!-- Defining the joints between the links -->
  <!-- World to basement joint -->
  <joint name="virtual_joint" type="fixed">
    <parent link="world"/>
    <child link="base_link"/>
    <origin rpy="0 0 0" xyz="0 0 0"/>
  </joint>
  <!-- Basement to base_plate joint -->
  <joint name="basement_to_base_plate" type="revolute">
    <parent link="base_link"/>
    <child link="base_plate"/>
    <axis xyz="0 0 1"/>
    <!-- Rotation around Z-axis -->
    <origin rpy="0 0 0" xyz="0 0 0.307"/>
    <limit effort="30.0" lower="-1.570795" upper="1.570795" velocity="10.0"/>
    <!-- Joint limits: upper(90 degrees) and lower(-90 degree) are angles in radians -->
  </joint>
  <!-- Base_plate to forward_drive_arm joint -->
  <joint name="base_plate_to_forward_drive_arm" type="revolute">
    <parent link="base_plate"/>
    <child link="forward_drive_arm"/>
    <axis xyz="1 0 0"/>
    <!-- Rotation around X-axis -->
    <origin rpy="0 0 0" xyz="-0.02 0.0 0.35"/>
    <limit effort="30.0" lower="-1.570795" upper="1.570795" velocity="10.0"/>
    <!-- Joint limits: upper(90 degrees) and lower(-90 degree) are angles in radians -->
  </joint>
  <!-- Forward_drive_arm to horizontal_arm joint -->
  <joint name="forward_drive_arm_to_horizontal_arm" type="revolute">
    <parent link="forward_drive_arm"/>
    <child link="horizontal_arm"/>
    <axis xyz="1 0 0"/>
    <!-- Rotation around X-axis -->
    <origin rpy="0 0 0" xyz="0.0 0.0 0.8"/>
    <limit effort="30.0" lower="-1.570795" upper="1.570795" velocity="10.0"/>
    <!-- Joint limits: upper(90 degrees) and lower(-90 degree) are angles in radians -->
  </joint>
  <!-- Horizontal_arm to claw_support joint -->
  <joint name="horizontal_arm_to_claw_support" type="fixed">
    <parent link="horizontal_arm"/>
    <child link="claw_support"/>
    <origin rpy="0 0 0" xyz="0.0 0.82 0.0"/>
    <!-- add limits to restrict the collision -->
  </joint>
  <!-- Claw_support to gripper_finger_left joint -->
  <joint name="claw_support_to_gripper_finger_left" type="revolute">
    <parent link="claw_support"/>
    <child link="gripper_finger_left"/>
    <origin rpy="0 0 0" xyz="-0.22 0.13 -0.1"/>
    <axis xyz="0 0 1"/>
    <!-- Rotation around Z-axis -->
    <limit effort="30.0" lower="0.0" upper="1.570795" velocity="10.0"/>
  </joint>
  <!-- Claw_support to gripper_finger_right joint -->
  <joint name="claw_support_to_gripper_finger_right" type="revolute">
    <parent link="claw_support"/>
    <child link="gripper_finger_right"/>
    <origin rpy="0 0 0" xyz="-0.048 0.13 -0.1"/>
    <axis xyz="0 0 1"/>
    <!-- Rotation around Z-axis -->
    <mimic joint="claw_support_to_gripper_finger_left" multiplier="-1.0"/>
    <limit effort="30.0" lower="-1.570795" upper="0.0" velocity="10.0"/>
  </joint>
  <!-- base_link to rgb_camera joint -->
  <joint name="rgb_camera_joint" type="fixed">
    <parent link="base_link"/>
    <child link="rgb_camera"/>
    <origin rpy="0 -0.5 1.57" xyz="0.0 0.45 0.2"/>
  </joint>
</robot>
